<mujoco model="B-20250522">
    <!--    <include file="scene.xml"/>-->
    <default>
        <default class="robot">
            <default class="motor">
                <joint/>
                <motor/>
            </default>
            <default class="visual">
                <geom material="default_material" contype="0" conaffinity="0" group="2"/>
            </default>
            <default class="collision">
                <geom material="collision_material" condim="3" contype="0" conaffinity="1" solref="0.005 1"
                      friction="1 0.01 0.001" density="0" group="1"/>
<!--                <equality solimp="0.99 0.999 1e-05" solref="0.005 1"/>-->
            </default>
        </default>
    </default>
    <compiler angle="radian" meshdir="./meshes/"/>
    <compiler autolimits="true"/>
    <asset>
        <material name="default_material" rgba="0.7 0.7 0.7 1"/>
        <material name="collision_material" rgba="0.0 0.4 0.8 0.2"/>
        <mesh name="base" file="base.stl"/>
        <mesh name="waist_z" file="waist_z.stl"/>
        <mesh name="waist_x" file="waist_x.stl"/>
        <mesh name="body" file="body.stl"/>
        <mesh name="shoulder_y" file="shoulder_y.stl"/>
        <mesh name="shoulder_x" file="shoulder_x.stl"/>
        <mesh name="shoulder_z" file="shoulder_z.stl"/>
        <mesh name="elbow" file="elbow.stl"/>
        <mesh name="wrist_z" file="wrist_z.stl"/>
        <mesh name="wrist_y" file="wrist_y.stl"/>
        <mesh name="wrist_x" file="wrist_x.stl"/>
        <mesh name="hip_y" file="hip_y.stl"/>
        <mesh name="hip_x" file="hip_x.stl"/>
        <mesh name="hip_z" file="hip_z.stl"/>
        <mesh name="knee" file="knee.stl"/>
        <mesh name="ankle_y" file="ankle_y.stl"/>
        <mesh name="ankle_x" file="ankle_x.stl"/>

        <texture name="texplane" type="2d" builtin="checker" rgb1=".2 .3 .4" rgb2=".1 0.15 0.2"
                 width="512" height="512"/>
        <!--        <material name='geom' texture="texgeom" texuniform="true"/>-->
        <material name='MatPlane' reflectance='0.3' texture="texplane" texrepeat="1 1" texuniform="true"/>
    </asset>

    <worldbody>
        <!-- 灯光 -->
        <light directional="true" pos="-0.5 0.5 3" dir="0 0 -1"/>
        <!--        <geom name="floor" pos="0 0 0" rgba="0.8 0.9 0.8 1" size="40 40 40" type="plane"/>-->
        <geom name='floor' pos='0 0 0' size='50 50 .125' type='plane' material="MatPlane" condim='3'
              friction="1 0.01 0.01" group="0"/>

        <body name="base_link" pos="0 0. 1." quat="1 0 0 0" childclass="robot">
            <freejoint name="floating_base"/>
            <site name="imu_site" pos="0. 0. -0.068" size="0.005" rgba="1 0 0 1"/>
            <site name="base_site" pos="0 0 0" quat="1 0 0 0"/>

            <geom type="mesh" mesh="base" class="visual"/>
            <geom size="0.09 0.065" quat="0.707107 0.707107 0 0" type="cylinder" class="collision"/>
            <body name="waist_z_link" pos="0 0 0.176">
                <inertial pos="-0.0274148 -0.0025889 0.240264" quat="0.915195 -0.0186902 -0.0284229 0.401573"
                          mass="22.9667"
                          diaginertia="0.542799 0.536002 0.1746"/>
                <joint name="waist_z_joint" pos="0 0 0" axis="0 0 1" range="-3.6652 1.7453"
                       actuatorfrcrange="-107 107"/>
                <geom type="mesh" mesh="waist_z" class="visual"/>
                <geom size="0.065 0.03" pos="0 0 -0.07" type="cylinder" class="collision"/>
                <geom type="mesh" mesh="waist_x" class="visual"/>
                <geom size="0.06 0.045 0.07" pos="0 0 0.03" type="box" class="collision"/>
                <geom pos="0 0 0.114" quat="1 0 0 0" type="mesh" mesh="body" class="visual"/>
                <geom size="0.1 0.1 0.1875" pos="-0.025 0 0.239" type="box" class="collision"/>
                <geom size="0.115 0.125 0.125" pos="-0.025 0 0.314" type="box" class="collision"/>
                <geom size="0.05 0.05" pos="-0.029 0 0.464" type="cylinder" class="collision"/>
                <geom size="0.1" pos="-0.01 0 0.594" class="collision"/>
                <body name="left_shoulder_y_link" pos="-0.03 0.22635 0.339">
                    <inertial pos="-0.00283 -0.01423 -0.00089" quat="0.54528 0.545862 -0.456723 0.442842" mass="1.82215"
                              diaginertia="0.00402614 0.00386441 0.00252945"/>
                    <joint name="left_shoulder_y_joint" pos="0 0 0" axis="0 1 0" range="-3.3161 1.5708"
                           actuatorfrcrange="-107 107"/>
                    <geom quat="0.707107 -0.707107 0 0" type="mesh" mesh="shoulder_y" class="visual"/>
                    <geom size="0.06 0.05" pos="0 -0.075 0" quat="0.707107 0.707107 0 0" type="cylinder"
                          class="collision"/>
                    <body name="left_shoulder_x_link">
                        <inertial pos="0.00263 0 -0.05349" quat="0.680193 -0.193229 -0.193229 0.680193" mass="0.97689"
                                  diaginertia="0.0031 0.00274687 0.00214313"/>
                        <joint name="left_shoulder_x_joint" pos="0 0 0" axis="1 0 0" range="-0.43633 3.5779"
                               actuatorfrcrange="-107 107"/>
                        <geom type="mesh" mesh="shoulder_x" class="visual"/>
                        <geom size="0.055 0.05" pos="0 0 -0.09" type="cylinder" class="collision"/>
                        <geom size="0.055 0.055" quat="0.707107 0 0.707107 0" type="cylinder" class="collision"/>
                        <body name="left_shoulder_z_link" pos="0 0 -0.265">
                            <inertial pos="-0.00978 -0.00126 0.09022" quat="0.999153 0.02114 -0.02756 -0.022052"
                                      mass="1.9789" diaginertia="0.00921773 0.00904872 0.00366355"/>
                            <joint name="left_shoulder_z_joint" pos="0 0 0" axis="0 0 1" range="-2.9671 2.9671"
                                   actuatorfrcrange="-107 107"/>
                            <geom type="mesh" mesh="shoulder_z" class="visual"/>
                            <geom size="0.055 0.075" pos="0 0 0.05" type="cylinder" class="collision"/>
                            <body name="left_elbow_link" quat="0.707107 0 -0.707107 0">
                                <inertial pos="0.000299609 0.000651208 -0.113234"
                                          quat="0.996031 -0.00273113 -0.00201705 0.0889431" mass="4.20881"
                                          diaginertia="0.0464779 0.0462857 0.00517074"/>
                                <joint name="left_elbow_joint" pos="0 0 0" axis="0 1 0" range="-0.767945 1.74533"
                                       actuatorfrcrange="-107 107"/>
                                <geom type="mesh" mesh="elbow" class="visual"/>
                                <geom size="0.055 0.055" quat="0.707107 0.707107 0 0" type="cylinder"
                                      class="collision"/>
                                <geom size="0.045 0.075" pos="0 0 -0.05" type="cylinder" class="collision"/>
                                <geom pos="0 0 -0.16" quat="1 0 0 0" type="mesh" mesh="wrist_z" class="visual"/>
                                <geom size="0.04 0.0475" pos="0 0 -0.16" quat="0.707107 0.707107 0 0" type="cylinder"
                                      class="collision"/>
                                <geom pos="0 0 -0.16" type="mesh" mesh="wrist_y" class="visual"/>
                                <geom size="0.04 0.045" pos="0 0 -0.24" quat="0.707107 0 0.707107 0" type="cylinder"
                                      class="collision"/>
                                <geom pos="0 0 -0.24" quat="1 0 0 0" type="mesh" mesh="wrist_x" class="visual"/>
                                <geom size="0.0425" pos="0 0 -0.3375" class="collision"/>
                            </body>
                        </body>
                    </body>
                </body>

                <body name="right_shoulder_y_link" pos="-0.03 -0.22635 0.339">
                    <inertial pos="-0.00283 0.01423 0.00089" quat="0.537666 0.552004 -0.449614 0.451724" mass="1.82215"
                              diaginertia="0.00402595 0.00386463 0.00252942"/>
                    <joint name="right_shoulder_y_joint" pos="0 0 0" axis="0 1 0" range="-3.3161 1.5708"
                           actuatorfrcrange="-107 107"/>
                    <geom quat="0.707107 0.707107 0 0" type="mesh"
                          mesh="shoulder_y" class="visual"/>
                    <geom size="0.06 0.05" pos="0 0.075 0" quat="0.707107 0.707107 0 0" type="cylinder"
                          class="collision"/>
                    <body name="right_shoulder_x_link">
                        <inertial pos="0.00263 0 -0.05349" quat="0.680193 0.193229 0.193229 0.680193" mass="0.97689"
                                  diaginertia="0.0031 0.00274687 0.00214313"/>
                        <joint name="right_shoulder_x_joint" pos="0 0 0" axis="1 0 0" range="-3.5779 0.43633"
                               actuatorfrcrange="-107 107"/>
                        <geom type="mesh" mesh="shoulder_x" class="visual"/>
                        <geom size="0.055 0.05" pos="0 0 -0.09" type="cylinder" class="collision"/>
                        <geom size="0.055 0.055" quat="0.707107 0 0.707107 0" type="cylinder" class="collision"/>
                        <body name="right_shoulder_z_link" pos="0 0 -0.265">
                            <inertial pos="-0.00978 -0.00126 0.09022" quat="0.999153 0.02114 -0.02756 -0.022052"
                                      mass="1.9789" diaginertia="0.00921773 0.00904872 0.00366355"/>
                            <joint name="right_shoulder_z_joint" pos="0 0 0" axis="0 0 1" range="-2.9671 2.9671"
                                   actuatorfrcrange="-107 107"/>
                            <geom type="mesh" mesh="shoulder_z" class="visual"/>
                            <geom size="0.055 0.075" pos="0 0 0.05" type="cylinder" class="collision"/>
                            <body name="right_elbow_link" quat="0.707107 0 -0.707107 0">
                                <inertial pos="0.000299609 0.000651208 -0.113925"
                                          quat="0.991919 -0.00272957 -0.00196078 0.126826" mass="4.20881"
                                          diaginertia="0.0470904 0.0469528 0.00517075"/>
                                <joint name="right_elbow_joint" pos="0 0 0" axis="0 1 0" range="-0.767945 1.74533"
                                       actuatorfrcrange="-107 107"/>
                                <geom type="mesh" mesh="elbow" class="visual"/>
                                <geom size="0.055 0.055" quat="0.707107 0.707107 0 0" type="cylinder"
                                      class="collision"/>
                                <geom size="0.045 0.075" pos="0 0 -0.05" type="cylinder" class="collision"/>
                                <geom pos="0 0 -0.16" quat="1 0 0 0" type="mesh"
                                      mesh="wrist_z" class="visual"/>
                                <geom size="0.04 0.0475" pos="0 0 -0.16" quat="0.707107 0.707107 0 0" type="cylinder"
                                      class="collision"/>
                                <geom pos="0 0 -0.16" type="mesh"
                                      mesh="wrist_y" class="visual"/>
                                <geom size="0.04 0.045" pos="0 0 -0.24" quat="0.707107 0 0.707107 0" type="cylinder"
                                      class="collision"/>
                                <geom pos="0 0 -0.24" quat="1 0 0 0" type="mesh"
                                      mesh="wrist_x" class="visual"/>
                                <geom size="0.0425" pos="0 0 -0.3375" class="collision"/>
                            </body>
                        </body>
                    </body>
                </body>
            </body>
            <body name="left_hip_y_link" pos="0 0.162 0">
                <inertial pos="-0.00121 -0.01442 -0.0003" quat="0.763796 0.642733 -0.0552737 -0.0213256" mass="1.89927"
                          diaginertia="0.00366741 0.003418 0.00310459"/>
                <joint name="left_hip_y_joint" pos="0 0 0" axis="0 1 0" range="-2.7925 1.5708"
                       actuatorfrcrange="-413 413"/>
                <geom quat="4.48966e-11 1 0 0" type="mesh"
                      mesh="hip_y" class="visual"/>
                <geom size="0.07 0.04" pos="0 -0.05 0" quat="0.707107 0.707107 0 0" type="cylinder" class="collision"
                />
                <geom size="0.06 0.0675" quat="0.707107 0 0.707107 0" type="cylinder" class="collision"/>
                <body name="left_hip_x_link">
                    <inertial pos="0.00153 0.00791 -0.07015" quat="0.702158 -0.0477966 -0.0427511 0.709128"
                              mass="1.75097"
                              diaginertia="0.00954042 0.00724071 0.00534887"/>
                    <joint name="left_hip_x_joint" pos="0 0 0" axis="1 0 0" range="-0.43633 2.618"
                           actuatorfrcrange="-107 107"/>
                    <geom quat="4.48966e-11 0 0 1" type="mesh"
                          mesh="hip_x" class="visual"/>
                    <geom size="0.07 0.04 0.075" pos="0 0 -0.05" type="box" class="collision"/>
                    <body name="left_hip_z_link" pos="0 0 -0.142">
                        <inertial pos="-0.00126 0.00032 -0.04122" quat="0.999978 -0.000703661 0.00164653 0.00637947"
                                  mass="3.59517" diaginertia="0.0492207 0.0476398 0.0126795"/>
                        <joint name="left_hip_z_joint" pos="0 0 0" axis="0 0 1" range="-0.5236 3.6652"
                               actuatorfrcrange="-107 107"/>
                        <geom type="mesh" mesh="hip_z" class="visual"/>
                        <geom size="0.06 0.13" pos="0 0 -0.12" type="cylinder" class="collision"/>
                        <body name="left_knee_link" pos="0 0 -0.278">
                            <inertial pos="-0.00065 0.00024 -0.10231" quat="0.99888 0.002419 0.0146062 -0.0449355"
                                      mass="4.66882" diaginertia="0.0963486 0.0956174 0.00965401"/>
                            <joint name="left_knee_joint" pos="0 0 0" axis="0 1 0" range="-0.17453 2.5307"
                                   actuatorfrcrange="-413 413"/>
                            <geom type="mesh" mesh="knee" class="visual"/>
                            <geom size="0.07 0.06" quat="0.707107 0.707107 0 0" type="cylinder" class="collision"
                            />
                            <geom size="0.055 0.15" pos="0 0 -0.2" type="cylinder" class="collision"/>
                            <body name="left_ankle_y_link" pos="0 0 -0.41">
                                <inertial pos="0.00233 -0.00031 -0.00088" quat="0.147007 0.700314 0.0210594 0.698216"
                                          mass="1.4119" diaginertia="0.00191483 0.00182875 0.00171641"/>
                                <joint name="left_ankle_y_joint" pos="0 0 0" axis="0 1 0" range="-1.0472 0.7854"
                                       actuatorfrcrange="-107 107"/>
                                <geom type="mesh" mesh="ankle_y" class="visual"/>
                                <geom size="0.045 0.055" quat="0.707107 0.707107 0 0" type="cylinder" class="collision"
                                />
                                <body name="left_ankle_x_link">
                                    <inertial pos="0.05253 8e-05 -0.0295" quat="0.480731 0.519412 0.515511 0.48307"
                                              mass="1.78979" diaginertia="0.01056 0.0104471 0.00311293"/>
                                    <joint name="left_ankle_x_joint" pos="0 0 0" axis="1 0 0" range="-0.61087 0.61087"
                                           actuatorfrcrange="-31 31"/>
                                    <geom type="mesh" mesh="ankle_x" class="visual"/>
                                    <geom size="0.105 0.06 0.02" pos="0.035 0 -0.05" type="box" class="collision"
                                    />
                                    <geom size="0.035" pos="0.16 0 -0.03" class="collision"/>
                                    <geom size="0.035" pos="0.14 0.025 -0.035" class="collision"/>
                                    <geom size="0.035" pos="0.14 -0.025 -0.035" class="collision"/>
                                    <geom size="0.035" pos="-0.06 0.025 -0.035" class="collision"/>
                                    <geom size="0.035" pos="-0.06 -0.025 -0.035" class="collision"/>
                                </body>
                            </body>
                        </body>
                    </body>
                </body>
            </body>
            <body name="right_hip_y_link" pos="0 -0.162 0">
                <inertial pos="0.00121 0.01442 -0.0003" quat="0.642733 0.763796 -0.0213256 -0.0552737" mass="1.89927"
                          diaginertia="0.00366741 0.003418 0.00310459"/>
                <joint name="right_hip_y_joint" pos="0 0 0" axis="0 1 0" range="-2.7925 1.5708"
                       actuatorfrcrange="-413 413"/>
                <geom type="mesh" mesh="hip_y" class="visual"/>
                <geom size="0.07 0.04" pos="0 0.05 0" quat="0.707107 0.707107 0 0" type="cylinder" class="collision"/>
                <geom size="0.06 0.0675" quat="0.707107 0 0.707107 0" type="cylinder" class="collision"/>
                <body name="right_hip_x_link">
                    <inertial pos="-0.00153 -0.00791 -0.07015" quat="0.702158 0.0477966 0.0427511 0.709128"
                              mass="1.75097"
                              diaginertia="0.00954042 0.00724071 0.00534887"/>
                    <joint name="right_hip_x_joint" pos="0 0 0" axis="1 0 0" range="-2.618 0.43633"
                           actuatorfrcrange="-107 107"/>
                    <geom type="mesh" mesh="hip_x" class="visual"/>
                    <geom size="0.07 0.04 0.075" pos="0 0 -0.05" type="box" class="collision"/>
                    <body name="right_hip_z_link" pos="0 0 -0.142">
                        <inertial pos="-0.00126 0.00032 -0.04122" quat="0.999979 0.000726316 0.00163749 0.00627329"
                                  mass="3.59517" diaginertia="0.0492206 0.0476398 0.0126795"/>
                        <joint name="right_hip_z_joint" pos="0 0 0" axis="0 0 1" range="-3.6652 0.5236"
                               actuatorfrcrange="-107 107"/>
                        <geom type="mesh" mesh="hip_z" class="visual"/>
                        <geom size="0.06 0.13" pos="0 0 -0.12" type="cylinder" class="collision"/>
                        <body name="right_knee_link" pos="0 0 -0.278">
                            <inertial pos="-0.00065 0.00024 -0.10231" quat="0.99888 0.002419 0.0146062 -0.0449355"
                                      mass="4.66882" diaginertia="0.0963486 0.0956174 0.00965401"/>
                            <joint name="right_knee_joint" pos="0 0 0" axis="0 1 0" range="-0.17453 2.5307"
                                   actuatorfrcrange="-413 413"/>
                            <geom type="mesh" mesh="knee" class="visual"/>
                            <geom size="0.07 0.06" quat="0.707107 0.707107 0 0" type="cylinder" class="collision"
                            />
                            <geom size="0.055 0.15" pos="0 0 -0.2" type="cylinder" class="collision"/>
                            <body name="right_ankle_y_link" pos="0 0 -0.41">
                                <inertial pos="0.00233 -0.00031 0.00088" quat="0.137386 0.700402 -3.02034e-08 0.700402"
                                          mass="1.4119" diaginertia="0.00192392 0.00182 0.00171608"/>
                                <joint name="right_ankle_y_joint" pos="0 0 0" axis="0 1 0" range="-1.0472 0.7854"
                                       actuatorfrcrange="-107 107"/>
                                <geom type="mesh" mesh="ankle_y" class="visual"/>
                                <geom size="0.045 0.055" quat="0.707107 0.707107 0 0" type="cylinder" class="collision"
                                />
                                <body name="right_ankle_x_link">
                                    <inertial pos="0.05253 8e-05 -0.0295" quat="0.480731 0.519412 0.515511 0.48307"
                                              mass="1.78979" diaginertia="0.01056 0.0104471 0.00311293"/>
                                    <joint name="right_ankle_x_joint" pos="0 0 0" axis="1 0 0" range="-0.61087 0.61087"
                                           actuatorfrcrange="-31 31"/>
                                    <geom type="mesh" mesh="ankle_x" class="visual"/>
                                    <geom size="0.105 0.06 0.02" pos="0.035 0 -0.05" type="box" class="collision"
                                    />
                                    <geom size="0.035" pos="0.16 0 -0.03" class="collision"/>
                                    <geom size="0.035" pos="0.14 0.025 -0.035" class="collision"/>
                                    <geom size="0.035" pos="0.14 -0.025 -0.035" class="collision"/>
                                    <geom size="0.035" pos="-0.06 0.025 -0.035" class="collision"/>
                                    <geom size="0.035" pos="-0.06 -0.025 -0.035" class="collision"/>
                                </body>
                            </body>
                        </body>
                    </body>
                </body>
            </body>

        </body>
    </worldbody>
    <actuator>
        <motor name="waist_z_joint_ctrl" joint="waist_z_joint" class="motor" gear="1" ctrlrange="-107 107"/>
        <motor name="left_shoulder_y_joint_ctrl" joint="left_shoulder_y_joint" class="motor" gear="1"
               ctrlrange="-107 107"/>
        <motor name="left_shoulder_x_joint_ctrl" joint="left_shoulder_x_joint" class="motor" gear="1"
               ctrlrange="-107 107"/>
        <motor name="left_shoulder_z_joint_ctrl" joint="left_shoulder_z_joint" class="motor" gear="1"
               ctrlrange="-107 107"/>
        <motor name="left_elbow_joint_ctrl" joint="left_elbow_joint" class="motor" gear="1" ctrlrange="-107 107"/>

        <motor name="right_shoulder_y_joint_ctrl" joint="right_shoulder_y_joint" class="motor" gear="1"
               ctrlrange="-107 107"/>
        <motor name="right_shoulder_x_joint_ctrl" joint="right_shoulder_x_joint" class="motor" gear="1"
               ctrlrange="-107 107"/>
        <motor name="right_shoulder_z_joint_ctrl" joint="right_shoulder_z_joint" class="motor" gear="1"
               ctrlrange="-107 107"/>
        <motor name="right_elbow_joint_ctrl" joint="right_elbow_joint" class="motor" gear="1" ctrlrange="-107 107"/>

        <motor name="left_hip_y_joint_ctrl" joint="left_hip_y_joint" class="motor" gear="1" ctrlrange="-413 413"/>
        <motor name="left_hip_x_joint_ctrl" joint="left_hip_x_joint" class="motor" gear="1" ctrlrange="-107 107"/>
        <motor name="left_hip_z_joint_ctrl" joint="left_hip_z_joint" class="motor" gear="1" ctrlrange="-107 107"/>
        <motor name="left_knee_joint_ctrl" joint="left_knee_joint" class="motor" gear="1" ctrlrange="-413 413"/>
        <motor name="left_ankle_y_joint_ctrl" joint="left_ankle_y_joint" class="motor" gear="1" ctrlrange="-107 107"/>
        <motor name="left_ankle_x_joint_ctrl" joint="left_ankle_x_joint" class="motor" gear="1" ctrlrange="-31 31"/>

        <motor name="right_hip_y_joint_ctrl" joint="right_hip_y_joint" class="motor" gear="1" ctrlrange="-413 413"/>
        <motor name="right_hip_x_joint_ctrl" joint="right_hip_x_joint" class="motor" gear="1" ctrlrange="-107 107"/>
        <motor name="right_hip_z_joint_ctrl" joint="right_hip_z_joint" class="motor" gear="1" ctrlrange="-107 107"/>
        <motor name="right_knee_joint_ctrl" joint="right_knee_joint" class="motor" gear="1" ctrlrange="-413 413"/>
        <motor name="right_ankle_y_joint_ctrl" joint="right_ankle_y_joint" class="motor" gear="1" ctrlrange="-107 107"/>
        <motor name="right_ankle_x_joint_ctrl" joint="right_ankle_x_joint" class="motor" gear="1" ctrlrange="-31 31"/>
    </actuator>

    <contact>
        <exclude body1="base_link" body2="waist_z_link"/>
        <!--        <exclude body1="waist_z_link" body2="body"/>-->

        <exclude body1="waist_z_link" body2="left_shoulder_y_link"/>
        <exclude body1="left_shoulder_y_link" body2="left_shoulder_x_link"/>
        <exclude body1="left_shoulder_x_link" body2="left_shoulder_z_link"/>
        <exclude body1="left_shoulder_x_link" body2="left_shoulder_z_link"/>
        <exclude body1="left_shoulder_z_link" body2="left_elbow_link"/>
        <!--        <exclude body1="left_elbow_link" body2="left_wrist_z_link"/>-->
        <!--        <exclude body1="left_wrist_z_link" body2="left_wrist_y_link"/>-->
        <!--        <exclude body1="left_wrist_y_link" body2="left_wrist_x_link"/>-->
        <!--        <exclude body1="left_wrist_y_link" body2="left_wrist_x_link"/>-->

        <exclude body1="waist_z_link" body2="right_shoulder_y_link"/>
        <exclude body1="right_shoulder_y_link" body2="right_shoulder_x_link"/>
        <exclude body1="right_shoulder_x_link" body2="right_shoulder_z_link"/>
        <exclude body1="right_shoulder_x_link" body2="right_shoulder_z_link"/>
        <exclude body1="right_shoulder_z_link" body2="right_elbow_link"/>
        <!--        <exclude body1="right_elbow_link" body2="right_wrist_z_link"/>-->
        <!--        <exclude body1="right_wrist_z_link" body2="right_wrist_y_link"/>-->
        <!--        <exclude body1="right_wrist_y_link" body2="right_wrist_x_link"/>-->
        <!--        <exclude body1="right_wrist_y_link" body2="right_wrist_x_link"/>-->

        <exclude body1="base_link" body2="left_hip_y_link"/>
        <exclude body1="left_hip_y_link" body2="left_hip_x_link"/>
        <exclude body1="left_hip_x_link" body2="left_hip_z_link"/>
        <exclude body1="left_hip_z_link" body2="left_knee_link"/>
        <exclude body1="left_knee_link" body2="left_ankle_y_link"/>
        <exclude body1="left_ankle_y_link" body2="left_ankle_x_link"/>

        <exclude body1="base_link" body2="right_hip_y_link"/>
        <exclude body1="right_hip_y_link" body2="right_hip_x_link"/>
        <exclude body1="right_hip_x_link" body2="right_hip_z_link"/>
        <exclude body1="right_hip_z_link" body2="right_knee_link"/>
        <exclude body1="right_knee_link" body2="right_ankle_y_link"/>
        <exclude body1="right_ankle_y_link" body2="right_ankle_x_link"/>
    </contact>


    <sensor>
        <!--        <framepos name="base_pos" objtype="site" objname="base_site"/>-->
        <framequat name="base_quat" objtype="site" objname="base_site"/>
        <!--        <framelinvel name="base_linvel" objtype="site" objname="base_site"/>-->
        <!--        <frameangvel name="base_angvel" objtype="site" objname="base_site"/>-->
        <!--        <velocimeter name="base_vel" site="base_site"/>-->
        <accelerometer site="imu_site"/>
        <gyro site="imu_site"/>

    </sensor>
</mujoco>
